<?xml version="1.0" encoding="utf-8"?>
<!-- This URDF was automatically created by SolidWorks to URDF Exporter! Originally created by Stephen Brawner (brawner@gmail.com) 
     Commit Version: 1.6.0-4-g7f85cfe  Build Version: 1.6.7995.38578
     For more information, please see http://wiki.ros.org/sw_urdf_exporter -->
<robot
  name="Robot_ERA">
  <link
    name="link_0">
    <inertial>
      <origin
        xyz="8.1811E-06 0.064148 0.028491"
        rpy="0 0 0" />
      <mass
        value="1.4573" />
      <inertia
        ixx="0.0028441"
        ixy="-6.1635E-07"
        ixz="9.4583E-08"
        iyy="0.0021256"
        iyz="-2.3032E-05"
        izz="0.0044372" />
    </inertial>
    <visual>
      <origin
        xyz="0 0 0"
        rpy="0 0 0" />
      <geometry>
        <mesh
          filename="package://Robot_ERA/meshes/link_0.STL" />
      </geometry>
      <material
        name="">
        <color
          rgba="0.75294 0.75294 0.75294 1" />
      </material>
    </visual>
    <collision>
      <origin
        xyz="0 0 0"
        rpy="0 0 0" />
      <geometry>
        <mesh
          filename="package://Robot_ERA/meshes/link_0.STL" />
      </geometry>
    </collision>
  </link>
  <link
    name="link_1">
    <inertial>
      <origin
        xyz="-8.8702E-05 0.078879 1.4751E-06"
        rpy="0 0 0" />
      <mass
        value="4.9252" />
      <inertia
        ixx="0.0097895"
        ixy="7.2357E-06"
        ixz="3.8633E-07"
        iyy="0.0085832"
        iyz="3.054E-07"
        izz="0.0070331" />
    </inertial>
    <visual>
      <origin
        xyz="0 0 0"
        rpy="0 0 0" />
      <geometry>
        <mesh
          filename="package://Robot_ERA/meshes/link_1.STL" />
      </geometry>
      <material
        name="">
        <color
          rgba="0.75294 0.75294 0.75294 1" />
      </material>
    </visual>
    <collision>
      <origin
        xyz="0 0 0"
        rpy="0 0 0" />
      <geometry>
        <mesh
          filename="package://Robot_ERA/meshes/link_1.STL" />
      </geometry>
    </collision>
  </link>
  <joint
    name="joint_1"
    type="revolute">
    <origin
      xyz="0 0 0.18918"
      rpy="-1.5708 0 -1.5708" />
    <parent
      link="link_0" />
    <child
      link="link_1" />
    <axis
      xyz="0 -1 0" />
    <limit
      lower="-2.3562"
      upper="2.3562"
      effort="1000"
      velocity="5" />
    <dynamics
      damping="0"
      friction="0" />
  </joint>
  <link
    name="link_2">
    <inertial>
      <origin
        xyz="-0.161262686422663 -0.000136692294061287 0.00782963077501263"
        rpy="0 0 0" />
      <mass
        value="2.97737093271591" />
      <inertia
        ixx="0.00395741063536685"
        ixy="-7.07177065142139E-06"
        ixz="3.50706079497186E-05"
        iyy="0.00625338013677876"
        iyz="1.23578595324686E-05"
        izz="0.00571589927544617" />
    </inertial>
    <visual>
      <origin
        xyz="0 0 0"
        rpy="0 0 0" />
      <geometry>
        <mesh
          filename="package://Robot_ERA/meshes/link_2.STL" />
      </geometry>
      <material
        name="">
        <color
          rgba="0.752941176470588 0.752941176470588 0.752941176470588 1" />
      </material>
    </visual>
    <collision>
      <origin
        xyz="0 0 0"
        rpy="0 0 0" />
      <geometry>
        <mesh
          filename="package://Robot_ERA/meshes/link_2.STL" />
      </geometry>
    </collision>
  </link>
  <joint
    name="joint_2"
    type="revolute">
    <origin
      xyz="0.00012374 -0.25568 0.00149"
      rpy="0 0 -1.5708" />
    <parent
      link="link_1" />
    <child
      link="link_2" />
    <axis
      xyz="0 0 1" />
    <limit
      lower="-1.5708"
      upper="1.5708"
      effort="45.1"
      velocity="0.114" />
    <dynamics
      damping="0"
      friction="0" />
  </joint>
  <link
    name="link_3">
    <inertial>
      <origin
        xyz="-0.000370885475026561 0.00229294620635992 0.21175082194751"
        rpy="0 0 0" />
      <mass
        value="1.40082730035319" />
      <inertia
        ixx="0.00418608582348625"
        ixy="-9.33789806278586E-06"
        ixz="2.72602723246539E-05"
        iyy="0.00424310951501921"
        iyz="0.000187610491595618"
        izz="0.000494915913062191" />
    </inertial>
    <visual>
      <origin
        xyz="0 0 0"
        rpy="0 0 0" />
      <geometry>
        <mesh
          filename="package://Robot_ERA/meshes/link_3.STL" />
      </geometry>
      <material
        name="">
        <color
          rgba="0.752941176470588 0.752941176470588 0.752941176470588 1" />
      </material>
    </visual>
    <collision>
      <origin
        xyz="0 0 0"
        rpy="0 0 0" />
      <geometry>
        <mesh
          filename="package://Robot_ERA/meshes/link_3.STL" />
      </geometry>
    </collision>
  </link>
  <joint
    name="joint_3"
    type="revolute">
    <origin
      xyz="0 0 0"
      rpy="-1.5708 0 0" />
    <parent
      link="link_2" />
    <child
      link="link_3" />
    <axis
      xyz="0 1 0" />
    <limit
      lower="-3.927"
      upper="0.7854"
      effort="22.7"
      velocity="0.114" />
    <dynamics
      damping="0"
      friction="0" />
  </joint>
  <link
    name="link_4">
    <inertial>
      <origin
        xyz="7.04690138048081E-06 0.00950257370630442 0.00737940778529238"
        rpy="0 0 0" />
      <mass
        value="0.346752223723456" />
      <inertia
        ixx="0.000135202143666052"
        ixy="-7.18609035495776E-08"
        ixz="3.024445323017E-08"
        iyy="0.00010581833342793"
        iyz="1.68938256287116E-05"
        izz="0.000173704607483614" />
    </inertial>
    <visual>
      <origin
        xyz="0 0 0"
        rpy="0 0 0" />
      <geometry>
        <mesh
          filename="package://Robot_ERA/meshes/link_4.STL" />
      </geometry>
      <material
        name="">
        <color
          rgba="0.752941176470588 0.752941176470588 0.752941176470588 1" />
      </material>
    </visual>
    <collision>
      <origin
        xyz="0 0 0"
        rpy="0 0 0" />
      <geometry>
        <mesh
          filename="package://Robot_ERA/meshes/link_4.STL" />
      </geometry>
    </collision>
  </link>
  <joint
    name="joint_4"
    type="revolute">
    <origin
      xyz="0 0 0.4284"
      rpy="-1.5708 0 -3.1416" />
    <parent
      link="link_3" />
    <child
      link="link_4" />
    <axis
      xyz="0 -1 0" />
    <limit
      lower="-2.3562"
      upper="2.3562"
      effort="0.5"
      velocity="8" />
    <dynamics
      damping="0"
      friction="0" />
  </joint>
  <link
    name="link_5">
    <inertial>
      <origin
        xyz="-1.37383912146571E-06 -0.100506212964361 -0.00174871909355217"
        rpy="0 0 0" />
      <mass
        value="0.155635640889723" />
      <inertia
        ixx="0.000134532482619006"
        ixy="3.98455352347092E-07"
        ixz="-1.05209048119545E-08"
        iyy="0.000175202779609289"
        iyz="-9.07655924945883E-06"
        izz="0.000104612213676861" />
    </inertial>
    <visual>
      <origin
        xyz="0 0 0"
        rpy="0 0 0" />
      <geometry>
        <mesh
          filename="package://Robot_ERA/meshes/link_5.STL" />
      </geometry>
      <material
        name="">
        <color
          rgba="0.752941176470588 0.752941176470588 0.752941176470588 1" />
      </material>
    </visual>
    <collision>
      <origin
        xyz="0 0 0"
        rpy="0 0 0" />
      <geometry>
        <mesh
          filename="package://Robot_ERA/meshes/link_5.STL" />
      </geometry>
    </collision>
  </link>
  <joint
    name="joint_5"
    type="revolute">
    <origin
      xyz="0.16115 0 0"
      rpy="0 0 -1.5708" />
    <parent
      link="link_4" />
    <child
      link="link_5" />
    <axis
      xyz="0 0 -1" />
    <limit
      lower="-3.927"
      upper="0.7854"
      effort="0.35"
      velocity="2" />
    <dynamics
      damping="0"
      friction="0" />
  </joint>
  <link
    name="link_6_1">
    <inertial>
      <origin
        xyz="8.89994597630395E-07 -0.0287485932369482 0.0151492418636834"
        rpy="0 0 0" />
      <mass
        value="0.01938707412012" />
      <inertia
        ixx="1.6008267590004E-05"
        ixy="2.87047684569698E-09"
        ixz="-1.75512776140931E-09"
        iyy="1.18412371032299E-05"
        iyz="2.6003521200431E-06"
        izz="2.53121364320976E-05" />
    </inertial>
    <visual>
      <origin
        xyz="0 0 0"
        rpy="0 0 0" />
      <geometry>
        <mesh
          filename="package://Robot_ERA/meshes/link_6_1.STL" />
      </geometry>
      <material
        name="">
        <color
          rgba="1 1 1 1" />
      </material>
    </visual>
    <collision>
      <origin
        xyz="0 0 0"
        rpy="0 0 0" />
      <geometry>
        <mesh
          filename="package://Robot_ERA/meshes/link_6_1.STL" />
      </geometry>
    </collision>
  </link>
  <joint
    name="joint_6_1"
    type="prismatic">
    <origin
      xyz="0 0 0"
      rpy="0 0 0" />
    <parent
      link="link_5" />
    <child
      link="link_6_1" />
    <axis
      xyz="0 0 -1" />
    <limit
      lower="0"
      upper="0.05"
      effort="0.1"
      velocity="0.05" />
    <dynamics
      damping="0"
      friction="0" />
  </joint>
  <link
    name="link_6_2">
    <inertial>
      <origin
        xyz="4.2571882107878E-06 -0.0288002672673087 0.0137283291343639"
        rpy="0 0 0" />
      <mass
        value="0.0194236693750671" />
      <inertia
        ixx="1.60362265953448E-05"
        ixy="-5.76686459490352E-10"
        ixz="2.14097697080715E-09"
        iyy="1.19054975416317E-05"
        iyz="2.59981373298728E-06"
        izz="2.54039078079099E-05" />
    </inertial>
    <visual>
      <origin
        xyz="0 0 0"
        rpy="0 0 0" />
      <geometry>
        <mesh
          filename="package://Robot_ERA/meshes/link_6_2.STL" />
      </geometry>
      <material
        name="">
        <color
          rgba="1 1 1 1" />
      </material>
    </visual>
    <collision>
      <origin
        xyz="0 0 0"
        rpy="0 0 0" />
      <geometry>
        <mesh
          filename="package://Robot_ERA/meshes/link_6_2.STL" />
      </geometry>
    </collision>
  </link>
  <joint
    name="joint_6_2"
    type="prismatic">
    <origin
      xyz="0 0 0"
      rpy="3.1416 0 3.1416" />
    <parent
      link="link_5" />
    <child
      link="link_6_2" />
    <axis
      xyz="0 0 1" />
    <limit
      lower="0"
      upper="0.05"
      effort="0.1"
      velocity="0.05" />
  </joint>
</robot>