<?xml version="1.0" encoding="utf-8"?>
<!-- This URDF was automatically created by SolidWorks to URDF Exporter! Originally created by Stephen Brawner (brawner@gmail.com) 
     Commit Version: 1.6.0-4-g7f85cfe  Build Version: 1.6.7995.38578
     For more information, please see http://wiki.ros.org/sw_urdf_exporter -->
<robot
  name="ERA">
  <link
    name="link_0">
    <inertial>
      <origin
        xyz="8.1811E-06 0.064148 0.028491"
        rpy="0 0 0" />
      <mass
        value="1.4573" />
      <inertia
        ixx="0.0028441"
        ixy="-6.1635E-07"
        ixz="9.4583E-08"
        iyy="0.0021256"
        iyz="-2.3032E-05"
        izz="0.0044372" />
    </inertial>
    <visual>
      <origin
        xyz="0 0 0"
        rpy="0 0 0" />
      <geometry>
        <mesh
          filename="package://ERA/meshes/link_0.STL" />
      </geometry>
      <material
        name="">
        <color
          rgba="0.75294 0.75294 0.75294 1" />
      </material>
    </visual>
    <collision>
      <origin
        xyz="0 0 0"
        rpy="0 0 0" />
      <geometry>
        <mesh
          filename="package://ERA/meshes/link_0.STL" />
      </geometry>
    </collision>
  </link>
  <link
    name="link_1">
    <inertial>
      <origin
        xyz="-8.8702E-05 0.078879 1.4751E-06"
        rpy="0 0 0" />
      <mass
        value="4.9252" />
      <inertia
        ixx="0.0097895"
        ixy="7.2357E-06"
        ixz="3.8633E-07"
        iyy="0.0085832"
        iyz="3.054E-07"
        izz="0.0070331" />
    </inertial>
    <visual>
      <origin
        xyz="0 0 0"
        rpy="0 0 0" />
      <geometry>
        <mesh
          filename="package://ERA/meshes/link_1.STL" />
      </geometry>
      <material
        name="">
        <color
          rgba="0.75294 0.75294 0.75294 1" />
      </material>
    </visual>
    <collision>
      <origin
        xyz="0 0 0"
        rpy="0 0 0" />
      <geometry>
        <mesh
          filename="package://ERA/meshes/link_1.STL" />
      </geometry>
    </collision>
  </link>
  <joint
    name="joint_1"
    type="revolute">
    <origin
      xyz="0 0 0.189175"
      rpy="-1.5707963267949 0 -1.57079632679489" />
    <parent
      link="link_0" />
    <child
      link="link_1" />
    <axis
      xyz="0 -1 0" />
    <limit
      lower="-2.3562"
      upper="2.3562"
      effort="7.1537"
      velocity="0.2188" />
    <dynamics
      damping="0"
      friction="0" />
  </joint>
  <link
    name="link_2">
    <inertial>
      <origin
        xyz="-0.161262686422663 -0.000136692294061287 0.00782963077501265"
        rpy="0 0 0" />
      <mass
        value="2.9773709327159" />
      <inertia
        ixx="0.00395741063536684"
        ixy="-7.0717706514214E-06"
        ixz="3.50706079497188E-05"
        iyy="0.00625338013677875"
        iyz="1.23578595324686E-05"
        izz="0.00571589927544615" />
    </inertial>
    <visual>
      <origin
        xyz="0 0 0"
        rpy="0 0 0" />
      <geometry>
        <mesh
          filename="package://ERA/meshes/link_2.STL" />
      </geometry>
      <material
        name="">
        <color
          rgba="0.752941176470588 0.752941176470588 0.752941176470588 1" />
      </material>
    </visual>
    <collision>
      <origin
        xyz="0 0 0"
        rpy="0 0 0" />
      <geometry>
        <mesh
          filename="package://ERA/meshes/link_2.STL" />
      </geometry>
    </collision>
  </link>
  <joint
    name="joint_2"
    type="revolute">
    <origin
      xyz="0.000123744699244387 -0.25567672725 0.00148999999984069"
      rpy="0 0 -1.5707963267949" />
    <parent
      link="link_1" />
    <child
      link="link_2" />
    <axis
      xyz="0 0 1" />
    <limit
      lower="-1.5708"
      upper="1.5708"
      effort="86.211"
      velocity="0.1163" />
    <dynamics
      damping="0"
      friction="0" />
  </joint>
  <link
    name="link_3">
    <inertial>
      <origin
        xyz="-0.000370885475026561 0.00229294620635992 0.21175082194751"
        rpy="0 0 0" />
      <mass
        value="1.40082730035319" />
      <inertia
        ixx="0.00418608582348626"
        ixy="-9.33789806278587E-06"
        ixz="2.72602723246538E-05"
        iyy="0.00424310951501921"
        iyz="0.000187610491595618"
        izz="0.000494915913062191" />
    </inertial>
    <visual>
      <origin
        xyz="0 0 0"
        rpy="0 0 0" />
      <geometry>
        <mesh
          filename="package://ERA/meshes/link_3.STL" />
      </geometry>
      <material
        name="">
        <color
          rgba="0.752941176470588 0.752941176470588 0.752941176470588 1" />
      </material>
    </visual>
    <collision>
      <origin
        xyz="0 0 0"
        rpy="0 0 0" />
      <geometry>
        <mesh
          filename="package://ERA/meshes/link_3.STL" />
      </geometry>
    </collision>
  </link>
  <joint
    name="joint_3"
    type="revolute">
    <origin
      xyz="0 0 0"
      rpy="-1.5707963267949 0 0" />
    <parent
      link="link_2" />
    <child
      link="link_3" />
    <axis
      xyz="0 1 0" />
    <limit
      lower="-3.927"
      upper="0.7854"
      effort="24.654"
      velocity="0.0635" />
    <dynamics
      damping="0"
      friction="0" />
  </joint>
  <link
    name="link_4">
    <inertial>
      <origin
        xyz="7.04690138053632E-06 0.00950257370630442 0.00737940778529239"
        rpy="0 0 0" />
      <mass
        value="0.346752223723456" />
      <inertia
        ixx="0.000135202143666052"
        ixy="-7.18609035495795E-08"
        ixz="3.02444532301698E-08"
        iyy="0.00010581833342793"
        iyz="1.68938256287117E-05"
        izz="0.000173704607483614" />
    </inertial>
    <visual>
      <origin
        xyz="0 0 0"
        rpy="0 0 0" />
      <geometry>
        <mesh
          filename="package://ERA/meshes/link_4.STL" />
      </geometry>
      <material
        name="">
        <color
          rgba="0.752941176470588 0.752941176470588 0.752941176470588 1" />
      </material>
    </visual>
    <collision>
      <origin
        xyz="0 0 0"
        rpy="0 0 0" />
      <geometry>
        <mesh
          filename="package://ERA/meshes/link_4.STL" />
      </geometry>
    </collision>
  </link>
  <joint
    name="joint_4"
    type="revolute">
    <origin
      xyz="0 0 0.428399999999979"
      rpy="-1.57079632679491 0 -3.1415926535893" />
    <parent
      link="link_3" />
    <child
      link="link_4" />
    <axis
      xyz="0 -1 0" />
    <limit
      lower="-2.3562"
      upper="2.3562"
      effort="15.93"
      velocity="0.0982" />
    <dynamics
      damping="0"
      friction="0" />
  </joint>
  <link
    name="link_5">
    <inertial>
      <origin
        xyz="-1.3738E-06 -0.10051 -0.0017487"
        rpy="0 0 0" />
      <mass
        value="0.15564" />
      <inertia
        ixx="0.00013453"
        ixy="3.9846E-07"
        ixz="-1.0521E-08"
        iyy="0.0001752"
        iyz="-9.0766E-06"
        izz="0.00010461" />
    </inertial>
    <visual>
      <origin
        xyz="0 0 0"
        rpy="0 0 0" />
      <geometry>
        <mesh
          filename="package://ERA/meshes/link_5.STL" />
      </geometry>
      <material
        name="">
        <color
          rgba="0.75294 0.75294 0.75294 1" />
      </material>
    </visual>
    <collision>
      <origin
        xyz="0 0 0"
        rpy="0 0 0" />
      <geometry>
        <mesh
          filename="package://ERA/meshes/link_5.STL" />
      </geometry>
    </collision>
  </link>
  <joint
    name="joint_5"
    type="revolute">
    <origin
      xyz="0.16115 0 0"
      rpy="0 0 -1.5708" />
    <parent
      link="link_4" />
    <child
      link="link_5" />
    <axis
      xyz="0 0 -1" />
    <limit
      lower="-3.927"
      upper="0.7854"
      effort="3.5"
      velocity="7.48" />
    <dynamics
      damping="0"
      friction="0" />
  </joint>
  <link
    name="link_6_1">
    <inertial>
      <origin
        xyz="8.8999E-07 -0.028749 0.015149"
        rpy="0 0 0" />
      <mass
        value="0.019387" />
      <inertia
        ixx="1.6008E-05"
        ixy="2.8705E-09"
        ixz="-1.7551E-09"
        iyy="1.1841E-05"
        iyz="2.6004E-06"
        izz="2.5312E-05" />
    </inertial>
    <visual>
      <origin
        xyz="0 0 0"
        rpy="0 0 0" />
      <geometry>
        <mesh
          filename="package://ERA/meshes/link_6_1.STL" />
      </geometry>
      <material
        name="">
        <color
          rgba="1 1 1 1" />
      </material>
    </visual>
    <collision>
      <origin
        xyz="0 0 0"
        rpy="0 0 0" />
      <geometry>
        <mesh
          filename="package://ERA/meshes/link_6_1.STL" />
      </geometry>
    </collision>
  </link>
  <joint
    name="joint_6_1"
    type="prismatic">
    <origin
      xyz="0 0 0"
      rpy="0 0 0" />
    <parent
      link="link_5" />
    <child
      link="link_6_1" />
    <axis
      xyz="0 0 -1" />
    <limit
      lower="0"
      upper="0.32"
      effort="218.75"
      velocity="0.016" />
    <dynamics
      damping="0"
      friction="0" />
  </joint>
  <link
    name="link_6_2">
    <inertial>
      <origin
        xyz="4.2572E-06 -0.0288 0.013728"
        rpy="0 0 0" />
      <mass
        value="0.019424" />
      <inertia
        ixx="1.6036E-05"
        ixy="-5.7669E-10"
        ixz="2.141E-09"
        iyy="1.1905E-05"
        iyz="2.5998E-06"
        izz="2.5404E-05" />
    </inertial>
    <visual>
      <origin
        xyz="0 0 0"
        rpy="0 0 0" />
      <geometry>
        <mesh
          filename="package://ERA/meshes/link_6_2.STL" />
      </geometry>
      <material
        name="">
        <color
          rgba="1 1 1 1" />
      </material>
    </visual>
    <collision>
      <origin
        xyz="0 0 0"
        rpy="0 0 0" />
      <geometry>
        <mesh
          filename="package://ERA/meshes/link_6_2.STL" />
      </geometry>
    </collision>
  </link>
  <joint
    name="joint_6_2"
    type="prismatic">
    <origin
      xyz="0 0 0"
      rpy="3.1416 0 3.1416" />
    <parent
      link="link_5" />
    <child
      link="link_6_2" />
    <axis
      xyz="0 0 1" />
    <limit
      lower="0"
      upper="0.05"
      effort="218.75"
      velocity="0.016" />
  </joint>
</robot>